Workbook

Sheet DASHBOARD MT POLA SEWA
B1: DASHBOARD DATA POLA SEWA
A2: =IFERROR(__xludf.DUMMYFUNCTION("QUERY( 'Data MT Pola Sewa'!$A$6:$AI$85, ""select * where U matches 'Akan Habis|Habis|Habis dalam 7-1 Hari' or W matches 'Akan Habis|Habis|Habis dalam 7-1 Hari' or Y matches 'Akan Habis|Habis|Habis dalam 7-1 Hari' or AA matches"&" 'Akan Habis|Habis|Habis dalam 7-1 Hari' or AC matches 'Akan Habis|Habis|Habis dalam 7-1 Hari' or AE matches 'Akan Habis|Habis|Habis dalam 7-1 Hari'"", 1 )"),"NO") -> NO | B2: =IFERROR(__xludf.DUMMYFUNCTION("""COMPUTED_VALUE"""),"NOPOL") -> NOPOL | C2: =IFERROR(__xludf.DUMMYFUNCTION("""COMPUTED_VALUE"""),"KAP") -> KAP | D2: =IFERROR(__xludf.DUMMYFUNCTION("""COMPUTED_VALUE"""),"") | E2: =IFERROR(__xludf.DUMMYFUNCTION("""COMPUTED_VALUE"""),"TRANSPORTIR") -> TRANSPORTIR | F2: =IFERROR(__xludf.DUMMYFUNCTION("""COMPUTED_VALUE"""),"TAHUN PEMBUATAN") -> TAHUN PEMBUATAN | G2: =IFERROR(__xludf.DUMMYFUNCTION("""COMPUTED_VALUE"""),"REGISTRASI") -> REGISTRASI | H2: =IFERROR(__xludf.DUMMYFUNCTION("""COMPUTED_VALUE"""),"MASA PEMAKAIAN HEAD") -> MASA PEMAKAIAN HEAD | I2: =IFERROR(__xludf.DUMMYFUNCTION("""COMPUTED_VALUE"""),"TYPE") -> TYPE | J2: =IFERROR(__xludf.DUMMYFUNCTION("""COMPUTED_VALUE"""),"CC") -> CC | K2: =IFERROR(__xludf.DUMMYFUNCTION("""COMPUTED_VALUE"""),"EMISI MESIN") -> EMISI MESIN | L2: =IFERROR(__xludf.DUMMYFUNCTION("""COMPUTED_VALUE"""),"JENIS (PTO/Standart)") -> JENIS (PTO/Standart) | M2: =IFERROR(__xludf.DUMMYFUNCTION("""COMPUTED_VALUE"""),"KAROSERI") -> KAROSERI | N2: =IFERROR(__xludf.DUMMYFUNCTION("""COMPUTED_VALUE"""),"TAHUN TANGKI") -> TAHUN TANGKI | O2: =IFERROR(__xludf.DUMMYFUNCTION("""COMPUTED_VALUE"""),"MASA PEMAKAIAN TANGKI") -> MASA PEMAKAIAN TANGKI | P2: =IFERROR(__xludf.DUMMYFUNCTION("""COMPUTED_VALUE"""),"MATERIAL TANGKI") -> MATERIAL TANGKI | Q2: =IFERROR(__xludf.DUMMYFUNCTION("""COMPUTED_VALUE"""),"MERK") -> MERK | R2: =IFERROR(__xludf.DUMMYFUNCTION("""COMPUTED_VALUE"""),"NO MESIN") -> NO MESIN | S2: =IFERROR(__xludf.DUMMYFUNCTION("""COMPUTED_VALUE"""),"NO RANGKA") -> NO RANGKA | T2: =IFERROR(__xludf.DUMMYFUNCTION("""COMPUTED_VALUE"""),"Tanggal STNK") -> Tanggal STNK | U2: =IFERROR(__xludf.DUMMYFUNCTION("""COMPUTED_VALUE"""),"Status") -> Status | V2: =IFERROR(__xludf.DUMMYFUNCTION("""COMPUTED_VALUE"""),"Tanggal PAJAK ") -> Tanggal PAJAK | W2: =IFERROR(__xludf.DUMMYFUNCTION("""COMPUTED_VALUE"""),"Status") -> Status | X2: =IFERROR(__xludf.DUMMYFUNCTION("""COMPUTED_VALUE"""),"Tanggal KEUR") -> Tanggal KEUR | Y2: =IFERROR(__xludf.DUMMYFUNCTION("""COMPUTED_VALUE"""),"Status") -> Status | Z2: =IFERROR(__xludf.DUMMYFUNCTION("""COMPUTED_VALUE"""),"Tanggal KIM") -> Tanggal KIM | AA2: =IFERROR(__xludf.DUMMYFUNCTION("""COMPUTED_VALUE"""),"Status") -> Status | AB2: =IFERROR(__xludf.DUMMYFUNCTION("""COMPUTED_VALUE"""),"Tanggal Tera") -> Tanggal Tera | AC2: =IFERROR(__xludf.DUMMYFUNCTION("""COMPUTED_VALUE"""),"Status") -> Status | AD2: =IFERROR(__xludf.DUMMYFUNCTION("""COMPUTED_VALUE"""),"Tanggal KEDAP") -> Tanggal KEDAP | AE2: =IFERROR(__xludf.DUMMYFUNCTION("""COMPUTED_VALUE"""),"Status") -> Status | AF2: =IFERROR(__xludf.DUMMYFUNCTION("""COMPUTED_VALUE"""),"Asuransi ") -> Asuransi | AG2: =IFERROR(__xludf.DUMMYFUNCTION("""COMPUTED_VALUE"""),"Status") -> Status | AH2: =IFERROR(__xludf.DUMMYFUNCTION("""COMPUTED_VALUE"""),"") | AI2: =IFERROR(__xludf.DUMMYFUNCTION("""COMPUTED_VALUE"""),"")
A3: =IFERROR(__xludf.DUMMYFUNCTION("""COMPUTED_VALUE"""),7.0) -> 7 | B3: =IFERROR(__xludf.DUMMYFUNCTION("""COMPUTED_VALUE"""),"B9300TFV") -> B9300TFV | C3: =IFERROR(__xludf.DUMMYFUNCTION("""COMPUTED_VALUE"""),"8+8") -> 8+8 | D3: =IFERROR(__xludf.DUMMYFUNCTION("""COMPUTED_VALUE"""),16.0) -> 16 | E3: =IFERROR(__xludf.DUMMYFUNCTION("""COMPUTED_VALUE"""),"PT. ADAM TRANS") -> PT. ADAM TRANS | F3: =IFERROR(__xludf.DUMMYFUNCTION("""COMPUTED_VALUE"""),2022.0) -> 2022 | G3: =IFERROR(__xludf.DUMMYFUNCTION("""COMPUTED_VALUE"""),2022.0) -> 2022 | H3: =IFERROR(__xludf.DUMMYFUNCTION("""COMPUTED_VALUE"""),4.0) -> 4 | I3: =IFERROR(__xludf.DUMMYFUNCTION("""COMPUTED_VALUE"""),"FL8JN2A-PGJ") -> FL8JN2A-PGJ | J3: =IFERROR(__xludf.DUMMYFUNCTION("""COMPUTED_VALUE"""),7684.0) -> 7684 | K3: =IFERROR(__xludf.DUMMYFUNCTION("""COMPUTED_VALUE"""),"EURO 4") -> EURO 4 | L3: =IFERROR(__xludf.DUMMYFUNCTION("""COMPUTED_VALUE"""),"Standart") -> Standart | M3: =IFERROR(__xludf.DUMMYFUNCTION("""COMPUTED_VALUE"""),"Geluran Adikarya") -> Geluran Adikarya | N3: =IFERROR(__xludf.DUMMYFUNCTION("""COMPUTED_VALUE"""),2022.0) -> 2022 | O3: =IFERROR(__xludf.DUMMYFUNCTION("""COMPUTED_VALUE"""),4.0) -> 4 | P3: =IFERROR(__xludf.DUMMYFUNCTION("""COMPUTED_VALUE"""),"CS") -> CS | Q3: =IFERROR(__xludf.DUMMYFUNCTION("""COMPUTED_VALUE"""),"HINO") -> HINO | R3: =IFERROR(__xludf.DUMMYFUNCTION("""COMPUTED_VALUE"""),"J08EWEJ12088") -> J08EWEJ12088 | S3: =IFERROR(__xludf.DUMMYFUNCTION("""COMPUTED_VALUE"""),"MJEFL8JN2NJP10126") -> MJEFL8JN2NJP10126 | T3: =IFERROR(__xludf.DUMMYFUNCTION("""COMPUTED_VALUE"""),46730.0) -> 46730 | U3: =IFERROR(__xludf.DUMMYFUNCTION("""COMPUTED_VALUE"""),"Berlaku") -> Berlaku | V3: =IFERROR(__xludf.DUMMYFUNCTION("""COMPUTED_VALUE"""),46365.0) -> 46365 | W3: =IFERROR(__xludf.DUMMYFUNCTION("""COMPUTED_VALUE"""),"Berlaku") -> Berlaku | Y3: =IFERROR(__xludf.DUMMYFUNCTION("""COMPUTED_VALUE"""),"Habis") -> Habis | Z3: =IFERROR(__xludf.DUMMYFUNCTION("""COMPUTED_VALUE"""),46303.0) -> 46303 | AA3: =IFERROR(__xludf.DUMMYFUNCTION("""COMPUTED_VALUE"""),"Akan Habis") -> Akan Habis | AB3: =IFERROR(__xludf.DUMMYFUNCTION("""COMPUTED_VALUE"""),46337.0) -> 46337 | AC3: =IFERROR(__xludf.DUMMYFUNCTION("""COMPUTED_VALUE"""),"Akan Habis") -> Akan Habis | AD3: =IFERROR(__xludf.DUMMYFUNCTION("""COMPUTED_VALUE"""),46347.0) -> 46347 | AE3: =IFERROR(__xludf.DUMMYFUNCTION("""COMPUTED_VALUE"""),"Berlaku") -> Berlaku | AF3: =IFERROR(__xludf.DUMMYFUNCTION("""COMPUTED_VALUE"""),"TUGU") -> TUGU | AG3: =IFERROR(__xludf.DUMMYFUNCTION("""COMPUTED_VALUE"""),"AKTIF ") -> AKTIF | AI3: =IFERROR(__xludf.DUMMYFUNCTION("""COMPUTED_VALUE"""),"R1880CK") -> R1880CK
A4: =IFERROR(__xludf.DUMMYFUNCTION("""COMPUTED_VALUE"""),8.0) -> 8 | B4: =IFERROR(__xludf.DUMMYFUNCTION("""COMPUTED_VALUE"""),"B9378TFV") -> B9378TFV | C4: =IFERROR(__xludf.DUMMYFUNCTION("""COMPUTED_VALUE"""),"8+8") -> 8+8 | D4: =IFERROR(__xludf.DUMMYFUNCTION("""COMPUTED_VALUE"""),16.0) -> 16 | E4: =IFERROR(__xludf.DUMMYFUNCTION("""COMPUTED_VALUE"""),"PT. ADAM TRANS") -> PT. ADAM TRANS | F4: =IFERROR(__xludf.DUMMYFUNCTION("""COMPUTED_VALUE"""),2023.0) -> 2023 | G4: =IFERROR(__xludf.DUMMYFUNCTION("""COMPUTED_VALUE"""),2023.0) -> 2023 | H4: =IFERROR(__xludf.DUMMYFUNCTION("""COMPUTED_VALUE"""),3.0) -> 3 | I4: =IFERROR(__xludf.DUMMYFUNCTION("""COMPUTED_VALUE"""),"2523 R/4500 6X2 MT") -> 2523 R/4500 6X2 MT | J4: =IFERROR(__xludf.DUMMYFUNCTION("""COMPUTED_VALUE"""),6374.0) -> 6374 | K4: =IFERROR(__xludf.DUMMYFUNCTION("""COMPUTED_VALUE"""),"EURO 5") -> EURO 5 | L4: =IFERROR(__xludf.DUMMYFUNCTION("""COMPUTED_VALUE"""),"Standart") -> Standart | M4: =IFERROR(__xludf.DUMMYFUNCTION("""COMPUTED_VALUE"""),"Meco") -> Meco | N4: =IFERROR(__xludf.DUMMYFUNCTION("""COMPUTED_VALUE"""),2023.0) -> 2023 | O4: =IFERROR(__xludf.DUMMYFUNCTION("""COMPUTED_VALUE"""),3.0) -> 3 | P4: =IFERROR(__xludf.DUMMYFUNCTION("""COMPUTED_VALUE"""),"CS") -> CS | Q4: =IFERROR(__xludf.DUMMYFUNCTION("""COMPUTED_VALUE"""),"MERCEDES BENZ") -> MERCEDES BENZ | R4: =IFERROR(__xludf.DUMMYFUNCTION("""COMPUTED_VALUE"""),"400952D0139091") -> 400952D0139091 | S4: =IFERROR(__xludf.DUMMYFUNCTION("""COMPUTED_VALUE"""),"MEC2126BAPP133277") -> MEC2126BAPP133277 | T4: =IFERROR(__xludf.DUMMYFUNCTION("""COMPUTED_VALUE"""),47025.0) -> 47025 | U4: =IFERROR(__xludf.DUMMYFUNCTION("""COMPUTED_VALUE"""),"Berlaku") -> Berlaku | V4: =IFERROR(__xludf.DUMMYFUNCTION("""COMPUTED_VALUE"""),46659.0) -> 46659 | W4: =IFERROR(__xludf.DUMMYFUNCTION("""COMPUTED_VALUE"""),"Berlaku") -> Berlaku | Y4: =IFERROR(__xludf.DUMMYFUNCTION("""COMPUTED_VALUE"""),"Habis") -> Habis | Z4: =IFERROR(__xludf.DUMMYFUNCTION("""COMPUTED_VALUE"""),46446.0) -> 46446 | AA4: =IFERROR(__xludf.DUMMYFUNCTION("""COMPUTED_VALUE"""),"Berlaku") -> Berlaku | AB4: =IFERROR(__xludf.DUMMYFUNCTION("""COMPUTED_VALUE"""),46688.0) -> 46688 | AC4: =IFERROR(__xludf.DUMMYFUNCTION("""COMPUTED_VALUE"""),"Berlaku") -> Berlaku | AD4: =IFERROR(__xludf.DUMMYFUNCTION("""COMPUTED_VALUE"""),46459.0) -> 46459 | AE4: =IFERROR(__xludf.DUMMYFUNCTION("""COMPUTED_VALUE"""),"Berlaku") -> Berlaku | AF4: =IFERROR(__xludf.DUMMYFUNCTION("""COMPUTED_VALUE"""),"TUGU") -> TUGU | AG4: =IFERROR(__xludf.DUMMYFUNCTION("""COMPUTED_VALUE"""),"AKTIF ") -> AKTIF | AI4: =IFERROR(__xludf.DUMMYFUNCTION("""COMPUTED_VALUE"""),"Menggantikan MT AA1895FP PT. TANAH PUTIH") -> Menggantikan MT AA1895FP PT. TANAH PUTIH
A5: =IFERROR(__xludf.DUMMYFUNCTION("""COMPUTED_VALUE"""),9.0) -> 9 | B5: =IFERROR(__xludf.DUMMYFUNCTION("""COMPUTED_VALUE"""),"B9376TFV") -> B9376TFV | C5: =IFERROR(__xludf.DUMMYFUNCTION("""COMPUTED_VALUE"""),"8+8") -> 8+8 | D5: =IFERROR(__xludf.DUMMYFUNCTION("""COMPUTED_VALUE"""),16.0) -> 16 | E5: =IFERROR(__xludf.DUMMYFUNCTION("""COMPUTED_VALUE"""),"PT. ADAM TRANS") -> PT. ADAM TRANS | F5: =IFERROR(__xludf.DUMMYFUNCTION("""COMPUTED_VALUE"""),2023.0) -> 2023 | G5: =IFERROR(__xludf.DUMMYFUNCTION("""COMPUTED_VALUE"""),2023.0) -> 2023 | H5: =IFERROR(__xludf.DUMMYFUNCTION("""COMPUTED_VALUE"""),3.0) -> 3 | I5: =IFERROR(__xludf.DUMMYFUNCTION("""COMPUTED_VALUE"""),"2523 R/4500 6X2 MT") -> 2523 R/4500 6X2 MT | J5: =IFERROR(__xludf.DUMMYFUNCTION("""COMPUTED_VALUE"""),6374.0) -> 6374 | K5: =IFERROR(__xludf.DUMMYFUNCTION("""COMPUTED_VALUE"""),"EURO 5") -> EURO 5 | L5: =IFERROR(__xludf.DUMMYFUNCTION("""COMPUTED_VALUE"""),"Standart") -> Standart | M5: =IFERROR(__xludf.DUMMYFUNCTION("""COMPUTED_VALUE"""),"Meco") -> Meco | N5: =IFERROR(__xludf.DUMMYFUNCTION("""COMPUTED_VALUE"""),2023.0) -> 2023 | O5: =IFERROR(__xludf.DUMMYFUNCTION("""COMPUTED_VALUE"""),3.0) -> 3 | P5: =IFERROR(__xludf.DUMMYFUNCTION("""COMPUTED_VALUE"""),"CS") -> CS | Q5: =IFERROR(__xludf.DUMMYFUNCTION("""COMPUTED_VALUE"""),"MERCEDES BENZ") -> MERCEDES BENZ | R5: =IFERROR(__xludf.DUMMYFUNCTION("""COMPUTED_VALUE"""),"400952D0139088") -> 400952D0139088 | S5: =IFERROR(__xludf.DUMMYFUNCTION("""COMPUTED_VALUE"""),"MEC2126BAPP133268") -> MEC2126BAPP133268 | T5: =IFERROR(__xludf.DUMMYFUNCTION("""COMPUTED_VALUE"""),47025.0) -> 47025 | U5: =IFERROR(__xludf.DUMMYFUNCTION("""COMPUTED_VALUE"""),"Berlaku") -> Berlaku | V5: =IFERROR(__xludf.DUMMYFUNCTION("""COMPUTED_VALUE"""),46659.0) -> 46659 | W5: =IFERROR(__xludf.DUMMYFUNCTION("""COMPUTED_VALUE"""),"Berlaku") -> Berlaku | Y5: =IFERROR(__xludf.DUMMYFUNCTION("""COMPUTED_VALUE"""),"Habis") -> Habis | Z5: =IFERROR(__xludf.DUMMYFUNCTION("""COMPUTED_VALUE"""),46447.0) -> 46447 | AA5: =IFERROR(__xludf.DUMMYFUNCTION("""COMPUTED_VALUE"""),"Berlaku") -> Berlaku | AB5: =IFERROR(__xludf.DUMMYFUNCTION("""COMPUTED_VALUE"""),46684.0) -> 46684 | AC5: =IFERROR(__xludf.DUMMYFUNCTION("""COMPUTED_VALUE"""),"Berlaku") -> Berlaku | AD5: =IFERROR(__xludf.DUMMYFUNCTION("""COMPUTED_VALUE"""),46459.0) -> 46459 | AE5: =IFERROR(__xludf.DUMMYFUNCTION("""COMPUTED_VALUE"""),"Berlaku") -> Berlaku | AF5: =IFERROR(__xludf.DUMMYFUNCTION("""COMPUTED_VALUE"""),"TUGU") -> TUGU | AG5: =IFERROR(__xludf.DUMMYFUNCTION("""COMPUTED_VALUE"""),"AKTIF ") -> AKTIF | AI5: =IFERROR(__xludf.DUMMYFUNCTION("""COMPUTED_VALUE"""),"Menggantikan MT AA1894FP PT. TANAH PUTIH") -> Menggantikan MT AA1894FP PT. TANAH PUTIH
A6: =IFERROR(__xludf.DUMMYFUNCTION("""COMPUTED_VALUE"""),10.0) -> 10 | B6: =IFERROR(__xludf.DUMMYFUNCTION("""COMPUTED_VALUE"""),"B9290TFV") -> B9290TFV | C6: =IFERROR(__xludf.DUMMYFUNCTION("""COMPUTED_VALUE"""),"8+8+8") -> 8+8+8 | D6: =IFERROR(__xludf.DUMMYFUNCTION("""COMPUTED_VALUE"""),24.0) -> 24 | E6: =IFERROR(__xludf.DUMMYFUNCTION("""COMPUTED_VALUE"""),"PT. ADAM TRANS") -> PT. ADAM TRANS | F6: =IFERROR(__xludf.DUMMYFUNCTION("""COMPUTED_VALUE"""),2022.0) -> 2022 | G6: =IFERROR(__xludf.DUMMYFUNCTION("""COMPUTED_VALUE"""),2022.0) -> 2022 | H6: =IFERROR(__xludf.DUMMYFUNCTION("""COMPUTED_VALUE"""),4.0) -> 4 | I6: =IFERROR(__xludf.DUMMYFUNCTION("""COMPUTED_VALUE"""),"SG8JF2B-XGJ") -> SG8JF2B-XGJ | J6: =IFERROR(__xludf.DUMMYFUNCTION("""COMPUTED_VALUE"""),7684.0) -> 7684 | K6: =IFERROR(__xludf.DUMMYFUNCTION("""COMPUTED_VALUE"""),"EURO 4") -> EURO 4 | L6: =IFERROR(__xludf.DUMMYFUNCTION("""COMPUTED_VALUE"""),"Standart") -> Standart | M6: =IFERROR(__xludf.DUMMYFUNCTION("""COMPUTED_VALUE"""),"Meco") -> Meco | N6: =IFERROR(__xludf.DUMMYFUNCTION("""COMPUTED_VALUE"""),2022.0) -> 2022 | O6: =IFERROR(__xludf.DUMMYFUNCTION("""COMPUTED_VALUE"""),4.0) -> 4 | P6: =IFERROR(__xludf.DUMMYFUNCTION("""COMPUTED_VALUE"""),"AA") -> AA | Q6: =IFERROR(__xludf.DUMMYFUNCTION("""COMPUTED_VALUE"""),"HINO") -> HINO | R6: =IFERROR(__xludf.DUMMYFUNCTION("""COMPUTED_VALUE"""),"J08EWDJ13408") -> J08EWDJ13408 | S6: =IFERROR(__xludf.DUMMYFUNCTION("""COMPUTED_VALUE"""),"MJESG8JF2NJX102576") -> MJESG8JF2NJX102576 | T6: =IFERROR(__xludf.DUMMYFUNCTION("""COMPUTED_VALUE"""),46713.0) -> 46713 | U6: =IFERROR(__xludf.DUMMYFUNCTION("""COMPUTED_VALUE"""),"Berlaku") -> Berlaku | V6: =IFERROR(__xludf.DUMMYFUNCTION("""COMPUTED_VALUE"""),46348.0) -> 46348 | W6: =IFERROR(__xludf.DUMMYFUNCTION("""COMPUTED_VALUE"""),"Berlaku") -> Berlaku | X6: =IFERROR(__xludf.DUMMYFUNCTION("""COMPUTED_VALUE"""),46303.0) -> 46303 | Y6: =IFERROR(__xludf.DUMMYFUNCTION("""COMPUTED_VALUE"""),"Akan Habis") -> Akan Habis | Z6: =IFERROR(__xludf.DUMMYFUNCTION("""COMPUTED_VALUE"""),46303.0) -> 46303 | AA6: =IFERROR(__xludf.DUMMYFUNCTION("""COMPUTED_VALUE"""),"Akan Habis") -> Akan Habis | AB6: =IFERROR(__xludf.DUMMYFUNCTION("""COMPUTED_VALUE"""),46548.0) -> 46548 | AC6: =IFERROR(__xludf.DUMMYFUNCTION("""COMPUTED_VALUE"""),"Berlaku") -> Berlaku | AD6: =IFERROR(__xludf.DUMMYFUNCTION("""COMPUTED_VALUE"""),46311.0) -> 46311 | AE6: =IFERROR(__xludf.DUMMYFUNCTION("""COMPUTED_VALUE"""),"Akan Habis") -> Akan Habis | AF6: =IFERROR(__xludf.DUMMYFUNCTION("""COMPUTED_VALUE"""),"TUGU") -> TUGU | AG6: =IFERROR(__xludf.DUMMYFUNCTION("""COMPUTED_VALUE"""),"AKTIF ") -> AKTIF | AI6: =IFERROR(__xludf.DUMMYFUNCTION("""COMPUTED_VALUE"""),"Menggantikan MT R 1892 DK PT Gelora yang afkir dan tidak diremajakan") -> Menggantikan MT R 1892 DK PT Gelora yang afkir dan tidak diremajakan
A7: =IFERROR(__xludf.DUMMYFUNCTION("""COMPUTED_VALUE"""),11.0) -> 11 | B7: =IFERROR(__xludf.DUMMYFUNCTION("""COMPUTED_VALUE"""),"B9355TFV") -> B9355TFV | C7: =IFERROR(__xludf.DUMMYFUNCTION("""COMPUTED_VALUE"""),"8+8+8") -> 8+8+8 | D7: =IFERROR(__xludf.DUMMYFUNCTION("""COMPUTED_VALUE"""),24.0) -> 24 | E7: =IFERROR(__xludf.DUMMYFUNCTION("""COMPUTED_VALUE"""),"PT. ADAM TRANS") -> PT. ADAM TRANS | F7: =IFERROR(__xludf.DUMMYFUNCTION("""COMPUTED_VALUE"""),2022.0) -> 2022 | G7: =IFERROR(__xludf.DUMMYFUNCTION("""COMPUTED_VALUE"""),2022.0) -> 2022 | H7: =IFERROR(__xludf.DUMMYFUNCTION("""COMPUTED_VALUE"""),4.0) -> 4 | I7: =IFERROR(__xludf.DUMMYFUNCTION("""COMPUTED_VALUE"""),"SG8JF2B-XGJ") -> SG8JF2B-XGJ | J7: =IFERROR(__xludf.DUMMYFUNCTION("""COMPUTED_VALUE"""),7684.0) -> 7684 | K7: =IFERROR(__xludf.DUMMYFUNCTION("""COMPUTED_VALUE"""),"EURO 4") -> EURO 4 | L7: =IFERROR(__xludf.DUMMYFUNCTION("""COMPUTED_VALUE"""),"Standart") -> Standart | M7: =IFERROR(__xludf.DUMMYFUNCTION("""COMPUTED_VALUE"""),"Meco") -> Meco | N7: =IFERROR(__xludf.DUMMYFUNCTION("""COMPUTED_VALUE"""),2022.0) -> 2022 | O7: =IFERROR(__xludf.DUMMYFUNCTION("""COMPUTED_VALUE"""),4.0) -> 4 | P7: =IFERROR(__xludf.DUMMYFUNCTION("""COMPUTED_VALUE"""),"AA") -> AA | Q7: =IFERROR(__xludf.DUMMYFUNCTION("""COMPUTED_VALUE"""),"HINO") -> HINO | R7: =IFERROR(__xludf.DUMMYFUNCTION("""COMPUTED_VALUE"""),"J08EWOJ13150") -> J08EWOJ13150 | S7: =IFERROR(__xludf.DUMMYFUNCTION("""COMPUTED_VALUE"""),"MJESG8JF2NJX10254") -> MJESG8JF2NJX10254 | T7: =IFERROR(__xludf.DUMMYFUNCTION("""COMPUTED_VALUE"""),46680.0) -> 46680 | U7: =IFERROR(__xludf.DUMMYFUNCTION("""COMPUTED_VALUE"""),"Berlaku") -> Berlaku | V7: =IFERROR(__xludf.DUMMYFUNCTION("""COMPUTED_VALUE"""),46315.0) -> 46315 | W7: =IFERROR(__xludf.DUMMYFUNCTION("""COMPUTED_VALUE"""),"Akan Habis") -> Akan Habis | X7: =IFERROR(__xludf.DUMMYFUNCTION("""COMPUTED_VALUE"""),46303.0) -> 46303 | Y7: =IFERROR(__xludf.DUMMYFUNCTION("""COMPUTED_VALUE"""),"Akan Habis") -> Akan Habis | Z7: =IFERROR(__xludf.DUMMYFUNCTION("""COMPUTED_VALUE"""),46303.0) -> 46303 | AA7: =IFERROR(__xludf.DUMMYFUNCTION("""COMPUTED_VALUE"""),"Akan Habis") -> Akan Habis | AB7: =IFERROR(__xludf.DUMMYFUNCTION("""COMPUTED_VALUE"""),46402.0) -> 46402 | AC7: =IFERROR(__xludf.DUMMYFUNCTION("""COMPUTED_VALUE"""),"Berlaku") -> Berlaku | AD7: =IFERROR(__xludf.DUMMYFUNCTION("""COMPUTED_VALUE"""),46311.0) -> 46311 | AE7: =IFERROR(__xludf.DUMMYFUNCTION("""COMPUTED_VALUE"""),"Akan Habis") -> Akan Habis | AF7: =IFERROR(__xludf.DUMMYFUNCTION("""COMPUTED_VALUE"""),"TUGU") -> TUGU | AG7: =IFERROR(__xludf.DUMMYFUNCTION("""COMPUTED_VALUE"""),"AKTIF ") -> AKTIF | AI7: =IFERROR(__xludf.DUMMYFUNCTION("""COMPUTED_VALUE"""),"Menggantikan MT R 1893 DK PT Gelora yang afkir dan tidak diremajakan") -> Menggantikan MT R 1893 DK PT Gelora yang afkir dan tidak diremajakan
A8: =IFERROR(__xludf.DUMMYFUNCTION("""COMPUTED_VALUE"""),12.0) -> 12 | B8: =IFERROR(__xludf.DUMMYFUNCTION("""COMPUTED_VALUE"""),"R8435CM") -> R8435CM | C8: =IFERROR(__xludf.DUMMYFUNCTION("""COMPUTED_VALUE"""),"8+8+8") -> 8+8+8 | D8: =IFERROR(__xludf.DUMMYFUNCTION("""COMPUTED_VALUE"""),24.0) -> 24 | E8: =IFERROR(__xludf.DUMMYFUNCTION("""COMPUTED_VALUE"""),"PT. KATRACO PUTRA SELARAS") -> PT. KATRACO PUTRA SELARAS | F8: =IFERROR(__xludf.DUMMYFUNCTION("""COMPUTED_VALUE"""),2022.0) -> 2022 | G8: =IFERROR(__xludf.DUMMYFUNCTION("""COMPUTED_VALUE"""),2022.0) -> 2022 | H8: =IFERROR(__xludf.DUMMYFUNCTION("""COMPUTED_VALUE"""),4.0) -> 4 | I8: =IFERROR(__xludf.DUMMYFUNCTION("""COMPUTED_VALUE"""),"SG8JF2B-XGJ (4X2)") -> SG8JF2B-XGJ (4X2) | J8: =IFERROR(__xludf.DUMMYFUNCTION("""COMPUTED_VALUE"""),7960.0) -> 7960 | K8: =IFERROR(__xludf.DUMMYFUNCTION("""COMPUTED_VALUE"""),"EURO 4") -> EURO 4 | L8: =IFERROR(__xludf.DUMMYFUNCTION("""COMPUTED_VALUE"""),"Standart") -> Standart | M8: =IFERROR(__xludf.DUMMYFUNCTION("""COMPUTED_VALUE"""),"Meco") -> Meco | N8: =IFERROR(__xludf.DUMMYFUNCTION("""COMPUTED_VALUE"""),2012.0) -> 2012 | O8: =IFERROR(__xludf.DUMMYFUNCTION("""COMPUTED_VALUE"""),14.0) -> 14 | P8: =IFERROR(__xludf.DUMMYFUNCTION("""COMPUTED_VALUE"""),"AA") -> AA | Q8: =IFERROR(__xludf.DUMMYFUNCTION("""COMPUTED_VALUE"""),"HINO") -> HINO | R8: =IFERROR(__xludf.DUMMYFUNCTION("""COMPUTED_VALUE"""),"J08EWDJ15223") -> J08EWDJ15223 | S8: =IFERROR(__xludf.DUMMYFUNCTION("""COMPUTED_VALUE"""),"MJESG8JF2NJX10417") -> MJESG8JF2NJX10417 | T8: =IFERROR(__xludf.DUMMYFUNCTION("""COMPUTED_VALUE"""),46708.0) -> 46708 | U8: =IFERROR(__xludf.DUMMYFUNCTION("""COMPUTED_VALUE"""),"Berlaku") -> Berlaku | V8: =IFERROR(__xludf.DUMMYFUNCTION("""COMPUTED_VALUE"""),46343.0) -> 46343 | W8: =IFERROR(__xludf.DUMMYFUNCTION("""COMPUTED_VALUE"""),"Akan Habis") -> Akan Habis | X8: =IFERROR(__xludf.DUMMYFUNCTION("""COMPUTED_VALUE"""),46352.0) -> 46352 | Y8: =IFERROR(__xludf.DUMMYFUNCTION("""COMPUTED_VALUE"""),"Berlaku") -> Berlaku | Z8: =IFERROR(__xludf.DUMMYFUNCTION("""COMPUTED_VALUE"""),46352.0) -> 46352 | AA8: =IFERROR(__xludf.DUMMYFUNCTION("""COMPUTED_VALUE"""),"Berlaku") -> Berlaku | AB8: =IFERROR(__xludf.DUMMYFUNCTION("""COMPUTED_VALUE"""),46339.0) -> 46339 | AC8: =IFERROR(__xludf.DUMMYFUNCTION("""COMPUTED_VALUE"""),"Akan Habis") -> Akan Habis | AD8: =IFERROR(__xludf.DUMMYFUNCTION("""COMPUTED_VALUE"""),46340.0) -> 46340 | AE8: =IFERROR(__xludf.DUMMYFUNCTION("""COMPUTED_VALUE"""),"Berlaku") -> Berlaku | AF8: =IFERROR(__xludf.DUMMYFUNCTION("""COMPUTED_VALUE"""),"TUGU") -> TUGU | AG8: =IFERROR(__xludf.DUMMYFUNCTION("""COMPUTED_VALUE"""),"AKTIF ") -> AKTIF
A9: =IFERROR(__xludf.DUMMYFUNCTION("""COMPUTED_VALUE"""),14.0) -> 14 | B9: =IFERROR(__xludf.DUMMYFUNCTION("""COMPUTED_VALUE"""),"B9697SFV") -> B9697SFV | C9: =IFERROR(__xludf.DUMMYFUNCTION("""COMPUTED_VALUE"""),"4+4") -> 4+4 | D9: =IFERROR(__xludf.DUMMYFUNCTION("""COMPUTED_VALUE"""),8.0) -> 8 | E9: =IFERROR(__xludf.DUMMYFUNCTION("""COMPUTED_VALUE"""),"PT. ELNUSA PETROFIN") -> PT. ELNUSA PETROFIN | F9: =IFERROR(__xludf.DUMMYFUNCTION("""COMPUTED_VALUE"""),2022.0) -> 2022 | G9: =IFERROR(__xludf.DUMMYFUNCTION("""COMPUTED_VALUE"""),2023.0) -> 2023 | H9: =IFERROR(__xludf.DUMMYFUNCTION("""COMPUTED_VALUE"""),4.0) -> 4 | I9: =IFERROR(__xludf.DUMMYFUNCTION("""COMPUTED_VALUE"""),"FG8JK2A-PGJ") -> FG8JK2A-PGJ | J9: =IFERROR(__xludf.DUMMYFUNCTION("""COMPUTED_VALUE"""),7684.0) -> 7684 | K9: =IFERROR(__xludf.DUMMYFUNCTION("""COMPUTED_VALUE"""),"EURO 4") -> EURO 4 | L9: =IFERROR(__xludf.DUMMYFUNCTION("""COMPUTED_VALUE"""),"Standart") -> Standart | M9: =IFERROR(__xludf.DUMMYFUNCTION("""COMPUTED_VALUE"""),"Geluran Adikarya") -> Geluran Adikarya | N9: =IFERROR(__xludf.DUMMYFUNCTION("""COMPUTED_VALUE"""),2023.0) -> 2023 | O9: =IFERROR(__xludf.DUMMYFUNCTION("""COMPUTED_VALUE"""),3.0) -> 3 | P9: =IFERROR(__xludf.DUMMYFUNCTION("""COMPUTED_VALUE"""),"CS") -> CS | Q9: =IFERROR(__xludf.DUMMYFUNCTION("""COMPUTED_VALUE"""),"HINO") -> HINO | R9: =IFERROR(__xludf.DUMMYFUNCTION("""COMPUTED_VALUE"""),"JO8EWEJ15259") -> JO8EWEJ15259 | S9: =IFERROR(__xludf.DUMMYFUNCTION("""COMPUTED_VALUE"""),"MJEFG8JK2NJP1018") -> MJEFG8JK2NJP1018 | T9: =IFERROR(__xludf.DUMMYFUNCTION("""COMPUTED_VALUE"""),46981.0) -> 46981 | U9: =IFERROR(__xludf.DUMMYFUNCTION("""COMPUTED_VALUE"""),"Berlaku") -> Berlaku | V9: =IFERROR(__xludf.DUMMYFUNCTION("""COMPUTED_VALUE"""),46615.0) -> 46615 | W9: =IFERROR(__xludf.DUMMYFUNCTION("""COMPUTED_VALUE"""),"Berlaku") -> Berlaku | Y9: =IFERROR(__xludf.DUMMYFUNCTION("""COMPUTED_VALUE"""),"Habis") -> Habis | Z9: =IFERROR(__xludf.DUMMYFUNCTION("""COMPUTED_VALUE"""),46424.0) -> 46424 | AA9: =IFERROR(__xludf.DUMMYFUNCTION("""COMPUTED_VALUE"""),"Berlaku") -> Berlaku | AB9: =IFERROR(__xludf.DUMMYFUNCTION("""COMPUTED_VALUE"""),46684.0) -> 46684 | AC9: =IFERROR(__xludf.DUMMYFUNCTION("""COMPUTED_VALUE"""),"Berlaku") -> Berlaku | AD9: =IFERROR(__xludf.DUMMYFUNCTION("""COMPUTED_VALUE"""),46340.0) -> 46340 | AE9: =IFERROR(__xludf.DUMMYFUNCTION("""COMPUTED_VALUE"""),"Berlaku") -> Berlaku | AF9: =IFERROR(__xludf.DUMMYFUNCTION("""COMPUTED_VALUE"""),"MANDIRI") -> MANDIRI | AG9: =IFERROR(__xludf.DUMMYFUNCTION("""COMPUTED_VALUE"""),"AKTIF ") -> AKTIF | AI9: =IFERROR(__xludf.DUMMYFUNCTION("""COMPUTED_VALUE"""),"Menggantikan MT AA1959EF PT. TANAH PUTIH") -> Menggantikan MT AA1959EF PT. TANAH PUTIH
A10: =IFERROR(__xludf.DUMMYFUNCTION("""COMPUTED_VALUE"""),15.0) -> 15 | B10: =IFERROR(__xludf.DUMMYFUNCTION("""COMPUTED_VALUE"""),"B9061SFV") -> B9061SFV | C10: =IFERROR(__xludf.DUMMYFUNCTION("""COMPUTED_VALUE"""),"8+8") -> 8+8 | D10: =IFERROR(__xludf.DUMMYFUNCTION("""COMPUTED_VALUE"""),16.0) -> 16 | E10: =IFERROR(__xludf.DUMMYFUNCTION("""COMPUTED_VALUE"""),"PT. ELNUSA PETROFIN") -> PT. ELNUSA PETROFIN | F10: =IFERROR(__xludf.DUMMYFUNCTION("""COMPUTED_VALUE"""),2018.0) -> 2018 | G10: =IFERROR(__xludf.DUMMYFUNCTION("""COMPUTED_VALUE"""),2018.0) -> 2018 | H10: =IFERROR(__xludf.DUMMYFUNCTION("""COMPUTED_VALUE"""),8.0) -> 8 | I10: =IFERROR(__xludf.DUMMYFUNCTION("""COMPUTED_VALUE"""),"CDE250 6X2R WB5100MM") -> CDE250 6X2R WB5100MM | J10: =IFERROR(__xludf.DUMMYFUNCTION("""COMPUTED_VALUE"""),7698.0) -> 7698 | K10: =IFERROR(__xludf.DUMMYFUNCTION("""COMPUTED_VALUE"""),"EURO 2") -> EURO 2 | L10: =IFERROR(__xludf.DUMMYFUNCTION("""COMPUTED_VALUE"""),"PTO") -> PTO | M10: =IFERROR(__xludf.DUMMYFUNCTION("""COMPUTED_VALUE"""),"Geluran Adikarya") -> Geluran Adikarya | N10: =IFERROR(__xludf.DUMMYFUNCTION("""COMPUTED_VALUE"""),2018.0) -> 2018 | O10: =IFERROR(__xludf.DUMMYFUNCTION("""COMPUTED_VALUE"""),8.0) -> 8 | P10: =IFERROR(__xludf.DUMMYFUNCTION("""COMPUTED_VALUE"""),"CS") -> CS | Q10: =IFERROR(__xludf.DUMMYFUNCTION("""COMPUTED_VALUE"""),"UD TRUCKS") -> UD TRUCKS | R10: =IFERROR(__xludf.DUMMYFUNCTION("""COMPUTED_VALUE"""),"GH8465224A1P") -> GH8465224A1P | S10: =IFERROR(__xludf.DUMMYFUNCTION("""COMPUTED_VALUE"""),"JPCZX22C8JT020521") -> JPCZX22C8JT020521 | T10: =IFERROR(__xludf.DUMMYFUNCTION("""COMPUTED_VALUE"""),46877.0) -> 46877 | U10: =IFERROR(__xludf.DUMMYFUNCTION("""COMPUTED_VALUE"""),"Berlaku") -> Berlaku | V10: =IFERROR(__xludf.DUMMYFUNCTION("""COMPUTED_VALUE"""),46511.0) -> 46511 | W10: =IFERROR(__xludf.DUMMYFUNCTION("""COMPUTED_VALUE"""),"Berlaku") -> Berlaku | Y10: =IFERROR(__xludf.DUMMYFUNCTION("""COMPUTED_VALUE"""),"Habis") -> Habis | Z10: =IFERROR(__xludf.DUMMYFUNCTION("""COMPUTED_VALUE"""),46424.0) -> 46424 | AA10: =IFERROR(__xludf.DUMMYFUNCTION("""COMPUTED_VALUE"""),"Berlaku") -> Berlaku | AB10: =IFERROR(__xludf.DUMMYFUNCTION("""COMPUTED_VALUE"""),46505.0) -> 46505 | AC10: =IFERROR(__xludf.DUMMYFUNCTION("""COMPUTED_VALUE"""),"Berlaku") -> Berlaku | AD10: =IFERROR(__xludf.DUMMYFUNCTION("""COMPUTED_VALUE"""),46340.0) -> 46340 | AE10: =IFERROR(__xludf.DUMMYFUNCTION("""COMPUTED_VALUE"""),"Berlaku") -> Berlaku | AF10: =IFERROR(__xludf.DUMMYFUNCTION("""COMPUTED_VALUE"""),"MANDIRI") -> MANDIRI | AG10: =IFERROR(__xludf.DUMMYFUNCTION("""COMPUTED_VALUE"""),"AKTIF ") -> AKTIF
A11: =IFERROR(__xludf.DUMMYFUNCTION("""COMPUTED_VALUE"""),16.0) -> 16 | B11: =IFERROR(__xludf.DUMMYFUNCTION("""COMPUTED_VALUE"""),"E9225YC") -> E9225YC | C11: =IFERROR(__xludf.DUMMYFUNCTION("""COMPUTED_VALUE"""),"8+8+8") -> 8+8+8 | D11: =IFERROR(__xludf.DUMMYFUNCTION("""COMPUTED_VALUE"""),24.0) -> 24 | E11: =IFERROR(__xludf.DUMMYFUNCTION("""COMPUTED_VALUE"""),"PT. PUSPITA CIPTA") -> PT. PUSPITA CIPTA | F11: =IFERROR(__xludf.DUMMYFUNCTION("""COMPUTED_VALUE"""),2022.0) -> 2022 | G11: =IFERROR(__xludf.DUMMYFUNCTION("""COMPUTED_VALUE"""),2022.0) -> 2022 | H11: =IFERROR(__xludf.DUMMYFUNCTION("""COMPUTED_VALUE"""),4.0) -> 4 | I11: =IFERROR(__xludf.DUMMYFUNCTION("""COMPUTED_VALUE"""),"SG8JF2B-XGJ") -> SG8JF2B-XGJ | J11: =IFERROR(__xludf.DUMMYFUNCTION("""COMPUTED_VALUE"""),7684.0) -> 7684 | K11: =IFERROR(__xludf.DUMMYFUNCTION("""COMPUTED_VALUE"""),"EURO 4") -> EURO 4 | L11: =IFERROR(__xludf.DUMMYFUNCTION("""COMPUTED_VALUE"""),"Standart") -> Standart | M11: =IFERROR(__xludf.DUMMYFUNCTION("""COMPUTED_VALUE"""),"Aweco") -> Aweco | N11: =IFERROR(__xludf.DUMMYFUNCTION("""COMPUTED_VALUE"""),2012.0) -> 2012 | O11: =IFERROR(__xludf.DUMMYFUNCTION("""COMPUTED_VALUE"""),14.0) -> 14 | P11: =IFERROR(__xludf.DUMMYFUNCTION("""COMPUTED_VALUE"""),"AA") -> AA | Q11: =IFERROR(__xludf.DUMMYFUNCTION("""COMPUTED_VALUE"""),"HINO") -> HINO | R11: =IFERROR(__xludf.DUMMYFUNCTION("""COMPUTED_VALUE"""),"J08EWDJ13442") -> J08EWDJ13442 | S11: =IFERROR(__xludf.DUMMYFUNCTION("""COMPUTED_VALUE"""),"MJESG8JF2NJX10278") -> MJESG8JF2NJX10278 | T11: =IFERROR(__xludf.DUMMYFUNCTION("""COMPUTED_VALUE"""),46672.0) -> 46672 | U11: =IFERROR(__xludf.DUMMYFUNCTION("""COMPUTED_VALUE"""),"Berlaku") -> Berlaku | V11: =IFERROR(__xludf.DUMMYFUNCTION("""COMPUTED_VALUE"""),46307.0) -> 46307 | W11: =IFERROR(__xludf.DUMMYFUNCTION("""COMPUTED_VALUE"""),"Akan Habis") -> Akan Habis | X11: =IFERROR(__xludf.DUMMYFUNCTION("""COMPUTED_VALUE"""),46315.0) -> 46315 | Y11: =IFERROR(__xludf.DUMMYFUNCTION("""COMPUTED_VALUE"""),"Akan Habis") -> Akan Habis | Z11: =IFERROR(__xludf.DUMMYFUNCTION("""COMPUTED_VALUE"""),46315.0) -> 46315 | AA11: =IFERROR(__xludf.DUMMYFUNCTION("""COMPUTED_VALUE"""),"Akan Habis") -> Akan Habis | AB11: =IFERROR(__xludf.DUMMYFUNCTION("""COMPUTED_VALUE"""),46437.0) -> 46437 | AC11: =IFERROR(__xludf.DUMMYFUNCTION("""COMPUTED_VALUE"""),"Berlaku") -> Berlaku | AD11: =IFERROR(__xludf.DUMMYFUNCTION("""COMPUTED_VALUE"""),46340.0) -> 46340 | AE11: =IFERROR(__xludf.DUMMYFUNCTION("""COMPUTED_VALUE"""),"Berlaku") -> Berlaku | AF11: =IFERROR(__xludf.DUMMYFUNCTION("""COMPUTED_VALUE"""),"TUGU") -> TUGU | AG11: =IFERROR(__xludf.DUMMYFUNCTION("""COMPUTED_VALUE"""),"AKTIF ") -> AKTIF | AI11: =IFERROR(__xludf.DUMMYFUNCTION("""COMPUTED_VALUE"""),"Menggantikan MT E 9632 YA sama-sama PT Puspita Cipta") -> Menggantikan MT E 9632 YA sama-sama PT Puspita Cipta
A12: =IFERROR(__xludf.DUMMYFUNCTION("""COMPUTED_VALUE"""),18.0) -> 18 | B12: =IFERROR(__xludf.DUMMYFUNCTION("""COMPUTED_VALUE"""),"E9334YC") -> E9334YC | C12: =IFERROR(__xludf.DUMMYFUNCTION("""COMPUTED_VALUE"""),"8+8+8") -> 8+8+8 | D12: =IFERROR(__xludf.DUMMYFUNCTION("""COMPUTED_VALUE"""),24.0) -> 24 | E12: =IFERROR(__xludf.DUMMYFUNCTION("""COMPUTED_VALUE"""),"PT. PUSPITA CIPTA") -> PT. PUSPITA CIPTA | F12: =IFERROR(__xludf.DUMMYFUNCTION("""COMPUTED_VALUE"""),2023.0) -> 2023 | G12: =IFERROR(__xludf.DUMMYFUNCTION("""COMPUTED_VALUE"""),2023.0) -> 2023 | H12: =IFERROR(__xludf.DUMMYFUNCTION("""COMPUTED_VALUE"""),3.0) -> 3 | I12: =IFERROR(__xludf.DUMMYFUNCTION("""COMPUTED_VALUE"""),"4028T") -> 4028T | J12: =IFERROR(__xludf.DUMMYFUNCTION("""COMPUTED_VALUE"""),6374.0) -> 6374 | K12: =IFERROR(__xludf.DUMMYFUNCTION("""COMPUTED_VALUE"""),"EURO 5") -> EURO 5 | L12: =IFERROR(__xludf.DUMMYFUNCTION("""COMPUTED_VALUE"""),"Standart") -> Standart | M12: =IFERROR(__xludf.DUMMYFUNCTION("""COMPUTED_VALUE"""),"Geluran Adikarya") -> Geluran Adikarya | N12: =IFERROR(__xludf.DUMMYFUNCTION("""COMPUTED_VALUE"""),2013.0) -> 2013 | O12: =IFERROR(__xludf.DUMMYFUNCTION("""COMPUTED_VALUE"""),13.0) -> 13 | P12: =IFERROR(__xludf.DUMMYFUNCTION("""COMPUTED_VALUE"""),"AA") -> AA | Q12: =IFERROR(__xludf.DUMMYFUNCTION("""COMPUTED_VALUE"""),"MERCEDES BENZ") -> MERCEDES BENZ | R12: =IFERROR(__xludf.DUMMYFUNCTION("""COMPUTED_VALUE"""),"400953D0141214") -> 400953D0141214 | S12: =IFERROR(__xludf.DUMMYFUNCTION("""COMPUTED_VALUE"""),"MFJ400262PJ002664") -> MFJ400262PJ002664 | T12: =IFERROR(__xludf.DUMMYFUNCTION("""COMPUTED_VALUE"""),47114.0) -> 47114 | U12: =IFERROR(__xludf.DUMMYFUNCTION("""COMPUTED_VALUE"""),"Berlaku") -> Berlaku | V12: =IFERROR(__xludf.DUMMYFUNCTION("""COMPUTED_VALUE"""),46383.0) -> 46383 | W12: =IFERROR(__xludf.DUMMYFUNCTION("""COMPUTED_VALUE"""),"Berlaku") -> Berlaku | X12: =IFERROR(__xludf.DUMMYFUNCTION("""COMPUTED_VALUE"""),46331.0) -> 46331 | Y12: =IFERROR(__xludf.DUMMYFUNCTION("""COMPUTED_VALUE"""),"Akan Habis") -> Akan Habis | Z12: =IFERROR(__xludf.DUMMYFUNCTION("""COMPUTED_VALUE"""),46331.0) -> 46331 | AA12: =IFERROR(__xludf.DUMMYFUNCTION("""COMPUTED_VALUE"""),"Berlaku") -> Berlaku | AB12: =IFERROR(__xludf.DUMMYFUNCTION("""COMPUTED_VALUE"""),46884.0) -> 46884 | AC12: =IFERROR(__xludf.DUMMYFUNCTION("""COMPUTED_VALUE"""),"Berlaku") -> Berlaku | AD12: =IFERROR(__xludf.DUMMYFUNCTION("""COMPUTED_VALUE"""),46360.0) -> 46360 | AE12: =IFERROR(__xludf.DUMMYFUNCTION("""COMPUTED_VALUE"""),"Berlaku") -> Berlaku | AF12: =IFERROR(__xludf.DUMMYFUNCTION("""COMPUTED_VALUE"""),"TUGU") -> TUGU | AG12: =IFERROR(__xludf.DUMMYFUNCTION("""COMPUTED_VALUE"""),"AKTIF ") -> AKTIF | AI12: =IFERROR(__xludf.DUMMYFUNCTION("""COMPUTED_VALUE"""),"Menggantikan MT E 9795 YA sama-sama PT Puspita Cipta afkir setelah dispensasi ke 4 tgl 27 Januari 2024") -> Menggantikan MT E 9795 YA sama-sama PT Puspita Cipta afkir setelah dispensasi ke 4 tgl 27 Januari 2024
A13: =IFERROR(__xludf.DUMMYFUNCTION("""COMPUTED_VALUE"""),19.0) -> 19 | B13: =IFERROR(__xludf.DUMMYFUNCTION("""COMPUTED_VALUE"""),"E9335YC") -> E9335YC | C13: =IFERROR(__xludf.DUMMYFUNCTION("""COMPUTED_VALUE"""),"8+8+8") -> 8+8+8 | D13: =IFERROR(__xludf.DUMMYFUNCTION("""COMPUTED_VALUE"""),24.0) -> 24 | E13: =IFERROR(__xludf.DUMMYFUNCTION("""COMPUTED_VALUE"""),"PT. PUSPITA CIPTA") -> PT. PUSPITA CIPTA | F13: =IFERROR(__xludf.DUMMYFUNCTION("""COMPUTED_VALUE"""),2023.0) -> 2023 | G13: =IFERROR(__xludf.DUMMYFUNCTION("""COMPUTED_VALUE"""),2023.0) -> 2023 | H13: =IFERROR(__xludf.DUMMYFUNCTION("""COMPUTED_VALUE"""),3.0) -> 3 | I13: =IFERROR(__xludf.DUMMYFUNCTION("""COMPUTED_VALUE"""),"4028T") -> 4028T | J13: =IFERROR(__xludf.DUMMYFUNCTION("""COMPUTED_VALUE"""),6374.0) -> 6374 | K13: =IFERROR(__xludf.DUMMYFUNCTION("""COMPUTED_VALUE"""),"EURO 5") -> EURO 5 | L13: =IFERROR(__xludf.DUMMYFUNCTION("""COMPUTED_VALUE"""),"Standart") -> Standart | M13: =IFERROR(__xludf.DUMMYFUNCTION("""COMPUTED_VALUE"""),"Geluran Adikarya") -> Geluran Adikarya | N13: =IFERROR(__xludf.DUMMYFUNCTION("""COMPUTED_VALUE"""),2013.0) -> 2013 | O13: =IFERROR(__xludf.DUMMYFUNCTION("""COMPUTED_VALUE"""),13.0) -> 13 | P13: =IFERROR(__xludf.DUMMYFUNCTION("""COMPUTED_VALUE"""),"AA") -> AA | Q13: =IFERROR(__xludf.DUMMYFUNCTION("""COMPUTED_VALUE"""),"MERCEDES BENZ") -> MERCEDES BENZ | R13: =IFERROR(__xludf.DUMMYFUNCTION("""COMPUTED_VALUE"""),"400953D0141220") -> 400953D0141220 | S13: =IFERROR(__xludf.DUMMYFUNCTION("""COMPUTED_VALUE"""),"MFJ400262PJ002663") -> MFJ400262PJ002663 | T13: =IFERROR(__xludf.DUMMYFUNCTION("""COMPUTED_VALUE"""),47114.0) -> 47114 | U13: =IFERROR(__xludf.DUMMYFUNCTION("""COMPUTED_VALUE"""),"Berlaku") -> Berlaku | V13: =IFERROR(__xludf.DUMMYFUNCTION("""COMPUTED_VALUE"""),46383.0) -> 46383 | W13: =IFERROR(__xludf.DUMMYFUNCTION("""COMPUTED_VALUE"""),"Berlaku") -> Berlaku | X13: =IFERROR(__xludf.DUMMYFUNCTION("""COMPUTED_VALUE"""),46331.0) -> 46331 | Y13: =IFERROR(__xludf.DUMMYFUNCTION("""COMPUTED_VALUE"""),"Akan Habis") -> Akan Habis | Z13: =IFERROR(__xludf.DUMMYFUNCTION("""COMPUTED_VALUE"""),46331.0) -> 46331 | AA13: =IFERROR(__xludf.DUMMYFUNCTION("""COMPUTED_VALUE"""),"Berlaku") -> Berlaku | AB13: =IFERROR(__xludf.DUMMYFUNCTION("""COMPUTED_VALUE"""),46912.0) -> 46912 | AC13: =IFERROR(__xludf.DUMMYFUNCTION("""COMPUTED_VALUE"""),"Berlaku") -> Berlaku | AD13: =IFERROR(__xludf.DUMMYFUNCTION("""COMPUTED_VALUE"""),46360.0) -> 46360 | AE13: =IFERROR(__xludf.DUMMYFUNCTION("""COMPUTED_VALUE"""),"Berlaku") -> Berlaku | AF13: =IFERROR(__xludf.DUMMYFUNCTION("""COMPUTED_VALUE"""),"TUGU") -> TUGU | AG13: =IFERROR(__xludf.DUMMYFUNCTION("""COMPUTED_VALUE"""),"AKTIF ") -> AKTIF | AI13: =IFERROR(__xludf.DUMMYFUNCTION("""COMPUTED_VALUE"""),"Menggantikan MT E 9854 YA sama-sama PT Puspita Cipta afkir setelah dispensasi 3 sd 27 Februari 2024") -> Menggantikan MT E 9854 YA sama-sama PT Puspita Cipta afkir setelah dispensasi 3 sd 27 Februari 2024
A14: =IFERROR(__xludf.DUMMYFUNCTION("""COMPUTED_VALUE"""),20.0) -> 20 | B14: =IFERROR(__xludf.DUMMYFUNCTION("""COMPUTED_VALUE"""),"E9412YC") -> E9412YC | C14: =IFERROR(__xludf.DUMMYFUNCTION("""COMPUTED_VALUE"""),"8+8+8") -> 8+8+8 | D14: =IFERROR(__xludf.DUMMYFUNCTION("""COMPUTED_VALUE"""),24.0) -> 24 | E14: =IFERROR(__xludf.DUMMYFUNCTION("""COMPUTED_VALUE"""),"PT. PUSPITA CIPTA") -> PT. PUSPITA CIPTA | F14: =IFERROR(__xludf.DUMMYFUNCTION("""COMPUTED_VALUE"""),2024.0) -> 2024 | G14: =IFERROR(__xludf.DUMMYFUNCTION("""COMPUTED_VALUE"""),2024.0) -> 2024 | H14: =IFERROR(__xludf.DUMMYFUNCTION("""COMPUTED_VALUE"""),2.0) -> 2 | I14: =IFERROR(__xludf.DUMMYFUNCTION("""COMPUTED_VALUE"""),"4028T") -> 4028T | J14: =IFERROR(__xludf.DUMMYFUNCTION("""COMPUTED_VALUE"""),6374.0) -> 6374 | K14: =IFERROR(__xludf.DUMMYFUNCTION("""COMPUTED_VALUE"""),"EURO 5") -> EURO 5 | L14: =IFERROR(__xludf.DUMMYFUNCTION("""COMPUTED_VALUE"""),"Standart") -> Standart | M14: =IFERROR(__xludf.DUMMYFUNCTION("""COMPUTED_VALUE"""),"Geluran Adikarya") -> Geluran Adikarya | N14: =IFERROR(__xludf.DUMMYFUNCTION("""COMPUTED_VALUE"""),2014.0) -> 2014 | O14: =IFERROR(__xludf.DUMMYFUNCTION("""COMPUTED_VALUE"""),12.0) -> 12 | P14: =IFERROR(__xludf.DUMMYFUNCTION("""COMPUTED_VALUE"""),"AA") -> AA | Q14: =IFERROR(__xludf.DUMMYFUNCTION("""COMPUTED_VALUE"""),"MERCEDES BENZ") -> MERCEDES BENZ | R14: =IFERROR(__xludf.DUMMYFUNCTION("""COMPUTED_VALUE"""),"400953D0157253") -> 400953D0157253 | S14: =IFERROR(__xludf.DUMMYFUNCTION("""COMPUTED_VALUE"""),"MFJ400262RJ003239") -> MFJ400262RJ003239 | T14: =IFERROR(__xludf.DUMMYFUNCTION("""COMPUTED_VALUE"""),47429.0) -> 47429 | U14: =IFERROR(__xludf.DUMMYFUNCTION("""COMPUTED_VALUE"""),"Berlaku") -> Berlaku | V14: =IFERROR(__xludf.DUMMYFUNCTION("""COMPUTED_VALUE"""),46333.0) -> 46333 | W14: =IFERROR(__xludf.DUMMYFUNCTION("""COMPUTED_VALUE"""),"Akan Habis") -> Akan Habis | X14: =IFERROR(__xludf.DUMMYFUNCTION("""COMPUTED_VALUE"""),46331.0) -> 46331 | Y14: =IFERROR(__xludf.DUMMYFUNCTION("""COMPUTED_VALUE"""),"Akan Habis") -> Akan Habis | Z14: =IFERROR(__xludf.DUMMYFUNCTION("""COMPUTED_VALUE"""),46331.0) -> 46331 | AA14: =IFERROR(__xludf.DUMMYFUNCTION("""COMPUTED_VALUE"""),"Berlaku") -> Berlaku | AB14: =IFERROR(__xludf.DUMMYFUNCTION("""COMPUTED_VALUE"""),46351.0) -> 46351 | AC14: =IFERROR(__xludf.DUMMYFUNCTION("""COMPUTED_VALUE"""),"Akan Habis") -> Akan Habis | AD14: =IFERROR(__xludf.DUMMYFUNCTION("""COMPUTED_VALUE"""),46340.0) -> 46340 | AE14: =IFERROR(__xludf.DUMMYFUNCTION("""COMPUTED_VALUE"""),"Berlaku") -> Berlaku | AF14: =IFERROR(__xludf.DUMMYFUNCTION("""COMPUTED_VALUE"""),"TUGU") -> TUGU | AG14: =IFERROR(__xludf.DUMMYFUNCTION("""COMPUTED_VALUE"""),"AKTIF ") -> AKTIF | AI14: =IFERROR(__xludf.DUMMYFUNCTION("""COMPUTED_VALUE"""),"Meremajakan MT E 9212 YB") -> Meremajakan MT E 9212 YB
A15: =IFERROR(__xludf.DUMMYFUNCTION("""COMPUTED_VALUE"""),23.0) -> 23 | B15: =IFERROR(__xludf.DUMMYFUNCTION("""COMPUTED_VALUE"""),"E9445YC") -> E9445YC | C15: =IFERROR(__xludf.DUMMYFUNCTION("""COMPUTED_VALUE"""),"8+8+8") -> 8+8+8 | D15: =IFERROR(__xludf.DUMMYFUNCTION("""COMPUTED_VALUE"""),24.0) -> 24 | E15: =IFERROR(__xludf.DUMMYFUNCTION("""COMPUTED_VALUE"""),"PT. PUSPITA CIPTA") -> PT. PUSPITA CIPTA | F15: =IFERROR(__xludf.DUMMYFUNCTION("""COMPUTED_VALUE"""),2024.0) -> 2024 | G15: =IFERROR(__xludf.DUMMYFUNCTION("""COMPUTED_VALUE"""),2024.0) -> 2024 | H15: =IFERROR(__xludf.DUMMYFUNCTION("""COMPUTED_VALUE"""),2.0) -> 2 | I15: =IFERROR(__xludf.DUMMYFUNCTION("""COMPUTED_VALUE"""),"4028T") -> 4028T | J15: =IFERROR(__xludf.DUMMYFUNCTION("""COMPUTED_VALUE"""),6374.0) -> 6374 | K15: =IFERROR(__xludf.DUMMYFUNCTION("""COMPUTED_VALUE"""),"EURO 5") -> EURO 5 | L15: =IFERROR(__xludf.DUMMYFUNCTION("""COMPUTED_VALUE"""),"Standart") -> Standart | M15: =IFERROR(__xludf.DUMMYFUNCTION("""COMPUTED_VALUE"""),"Geluran Adikarya") -> Geluran Adikarya | N15: =IFERROR(__xludf.DUMMYFUNCTION("""COMPUTED_VALUE"""),2014.0) -> 2014 | O15: =IFERROR(__xludf.DUMMYFUNCTION("""COMPUTED_VALUE"""),12.0) -> 12 | P15: =IFERROR(__xludf.DUMMYFUNCTION("""COMPUTED_VALUE"""),"AA") -> AA | Q15: =IFERROR(__xludf.DUMMYFUNCTION("""COMPUTED_VALUE"""),"MERCEDES BENZ") -> MERCEDES BENZ | R15: =IFERROR(__xludf.DUMMYFUNCTION("""COMPUTED_VALUE"""),"400953D0160558") -> 400953D0160558 | S15: =IFERROR(__xludf.DUMMYFUNCTION("""COMPUTED_VALUE"""),"MFJ400262RJ003564") -> MFJ400262RJ003564 | T15: =IFERROR(__xludf.DUMMYFUNCTION("""COMPUTED_VALUE"""),47475.0) -> 47475 | U15: =IFERROR(__xludf.DUMMYFUNCTION("""COMPUTED_VALUE"""),"Berlaku") -> Berlaku | V15: =IFERROR(__xludf.DUMMYFUNCTION("""COMPUTED_VALUE"""),46379.0) -> 46379 | W15: =IFERROR(__xludf.DUMMYFUNCTION("""COMPUTED_VALUE"""),"Berlaku") -> Berlaku | X15: =IFERROR(__xludf.DUMMYFUNCTION("""COMPUTED_VALUE"""),46332.0) -> 46332 | Y15: =IFERROR(__xludf.DUMMYFUNCTION("""COMPUTED_VALUE"""),"Akan Habis") -> Akan Habis | Z15: =IFERROR(__xludf.DUMMYFUNCTION("""COMPUTED_VALUE"""),46332.0) -> 46332 | AA15: =IFERROR(__xludf.DUMMYFUNCTION("""COMPUTED_VALUE"""),"Berlaku") -> Berlaku | AB15: =IFERROR(__xludf.DUMMYFUNCTION("""COMPUTED_VALUE"""),46452.0) -> 46452 | AC15: =IFERROR(__xludf.DUMMYFUNCTION("""COMPUTED_VALUE"""),"Berlaku") -> Berlaku | AD15: =IFERROR(__xludf.DUMMYFUNCTION("""COMPUTED_VALUE"""),46340.0) -> 46340 | AE15: =IFERROR(__xludf.DUMMYFUNCTION("""COMPUTED_VALUE"""),"Berlaku") -> Berlaku | AF15: =IFERROR(__xludf.DUMMYFUNCTION("""COMPUTED_VALUE"""),"TUGU") -> TUGU | AG15: =IFERROR(__xludf.DUMMYFUNCTION("""COMPUTED_VALUE"""),"AKTIF ") -> AKTIF | AI15: =IFERROR(__xludf.DUMMYFUNCTION("""COMPUTED_VALUE"""),"Meremajakan MT E9330YB") -> Meremajakan MT E9330YB
A16: =IFERROR(__xludf.DUMMYFUNCTION("""COMPUTED_VALUE"""),24.0) -> 24 | B16: =IFERROR(__xludf.DUMMYFUNCTION("""COMPUTED_VALUE"""),"E9552YC") -> E9552YC | C16: =IFERROR(__xludf.DUMMYFUNCTION("""COMPUTED_VALUE"""),"8+8+8") -> 8+8+8 | D16: =IFERROR(__xludf.DUMMYFUNCTION("""COMPUTED_VALUE"""),24.0) -> 24 | E16: =IFERROR(__xludf.DUMMYFUNCTION("""COMPUTED_VALUE"""),"PT. PUSPITA CIPTA") -> PT. PUSPITA CIPTA | F16: =IFERROR(__xludf.DUMMYFUNCTION("""COMPUTED_VALUE"""),2025.0) -> 2025 | G16: =IFERROR(__xludf.DUMMYFUNCTION("""COMPUTED_VALUE"""),2025.0) -> 2025 | H16: =IFERROR(__xludf.DUMMYFUNCTION("""COMPUTED_VALUE"""),1.0) -> 1 | I16: =IFERROR(__xludf.DUMMYFUNCTION("""COMPUTED_VALUE"""),"4028T") -> 4028T | J16: =IFERROR(__xludf.DUMMYFUNCTION("""COMPUTED_VALUE"""),6374.0) -> 6374 | K16: =IFERROR(__xludf.DUMMYFUNCTION("""COMPUTED_VALUE"""),"EURO 5") -> EURO 5 | L16: =IFERROR(__xludf.DUMMYFUNCTION("""COMPUTED_VALUE"""),"Standart") -> Standart | M16: =IFERROR(__xludf.DUMMYFUNCTION("""COMPUTED_VALUE"""),"Geluran Adikarya") -> Geluran Adikarya | N16: =IFERROR(__xludf.DUMMYFUNCTION("""COMPUTED_VALUE"""),2015.0) -> 2015 | O16: =IFERROR(__xludf.DUMMYFUNCTION("""COMPUTED_VALUE"""),11.0) -> 11 | P16: =IFERROR(__xludf.DUMMYFUNCTION("""COMPUTED_VALUE"""),"AA") -> AA | Q16: =IFERROR(__xludf.DUMMYFUNCTION("""COMPUTED_VALUE"""),"MERCEDES BENZ") -> MERCEDES BENZ | R16: =IFERROR(__xludf.DUMMYFUNCTION("""COMPUTED_VALUE"""),"400953D0195229") -> 400953D0195229 | S16: =IFERROR(__xludf.DUMMYFUNCTION("""COMPUTED_VALUE"""),"MFJ400262SJ004827") -> MFJ400262SJ004827 | T16: =IFERROR(__xludf.DUMMYFUNCTION("""COMPUTED_VALUE"""),47833.0) -> 47833 | U16: =IFERROR(__xludf.DUMMYFUNCTION("""COMPUTED_VALUE"""),"Berlaku") -> Berlaku | V16: =IFERROR(__xludf.DUMMYFUNCTION("""COMPUTED_VALUE"""),46372.0) -> 46372 | W16: =IFERROR(__xludf.DUMMYFUNCTION("""COMPUTED_VALUE"""),"Berlaku") -> Berlaku | X16: =IFERROR(__xludf.DUMMYFUNCTION("""COMPUTED_VALUE"""),46332.0) -> 46332 | Y16: =IFERROR(__xludf.DUMMYFUNCTION("""COMPUTED_VALUE"""),"Akan Habis") -> Akan Habis | Z16: =IFERROR(__xludf.DUMMYFUNCTION("""COMPUTED_VALUE"""),46332.0) -> 46332 | AA16: =IFERROR(__xludf.DUMMYFUNCTION("""COMPUTED_VALUE"""),"Berlaku") -> Berlaku | AB16: =IFERROR(__xludf.DUMMYFUNCTION("""COMPUTED_VALUE"""),46814.0) -> 46814 | AC16: =IFERROR(__xludf.DUMMYFUNCTION("""COMPUTED_VALUE"""),"Berlaku") -> Berlaku | AD16: =IFERROR(__xludf.DUMMYFUNCTION("""COMPUTED_VALUE"""),46459.0) -> 46459 | AE16: =IFERROR(__xludf.DUMMYFUNCTION("""COMPUTED_VALUE"""),"Berlaku") -> Berlaku | AF16: =IFERROR(__xludf.DUMMYFUNCTION("""COMPUTED_VALUE"""),"TUGU") -> TUGU | AG16: =IFERROR(__xludf.DUMMYFUNCTION("""COMPUTED_VALUE"""),"AKTIF ") -> AKTIF | AI16: =IFERROR(__xludf.DUMMYFUNCTION("""COMPUTED_VALUE"""),"Peremajaan E9553YB") -> Peremajaan E9553YB
A17: =IFERROR(__xludf.DUMMYFUNCTION("""COMPUTED_VALUE"""),25.0) -> 25 | B17: =IFERROR(__xludf.DUMMYFUNCTION("""COMPUTED_VALUE"""),"E9554YC") -> E9554YC | C17: =IFERROR(__xludf.DUMMYFUNCTION("""COMPUTED_VALUE"""),"8+8+8") -> 8+8+8 | D17: =IFERROR(__xludf.DUMMYFUNCTION("""COMPUTED_VALUE"""),24.0) -> 24 | E17: =IFERROR(__xludf.DUMMYFUNCTION("""COMPUTED_VALUE"""),"PT. PUSPITA CIPTA") -> PT. PUSPITA CIPTA | F17: =IFERROR(__xludf.DUMMYFUNCTION("""COMPUTED_VALUE"""),2025.0) -> 2025 | G17: =IFERROR(__xludf.DUMMYFUNCTION("""COMPUTED_VALUE"""),2025.0) -> 2025 | H17: =IFERROR(__xludf.DUMMYFUNCTION("""COMPUTED_VALUE"""),1.0) -> 1 | I17: =IFERROR(__xludf.DUMMYFUNCTION("""COMPUTED_VALUE"""),"4028T") -> 4028T | J17: =IFERROR(__xludf.DUMMYFUNCTION("""COMPUTED_VALUE"""),6374.0) -> 6374 | K17: =IFERROR(__xludf.DUMMYFUNCTION("""COMPUTED_VALUE"""),"EURO 5") -> EURO 5 | L17: =IFERROR(__xludf.DUMMYFUNCTION("""COMPUTED_VALUE"""),"Standart") -> Standart | M17: =IFERROR(__xludf.DUMMYFUNCTION("""COMPUTED_VALUE"""),"Geluran Adikarya") -> Geluran Adikarya | N17: =IFERROR(__xludf.DUMMYFUNCTION("""COMPUTED_VALUE"""),2015.0) -> 2015 | O17: =IFERROR(__xludf.DUMMYFUNCTION("""COMPUTED_VALUE"""),11.0) -> 11 | P17: =IFERROR(__xludf.DUMMYFUNCTION("""COMPUTED_VALUE"""),"AA") -> AA | Q17: =IFERROR(__xludf.DUMMYFUNCTION("""COMPUTED_VALUE"""),"MERCEDES BENZ") -> MERCEDES BENZ | R17: =IFERROR(__xludf.DUMMYFUNCTION("""COMPUTED_VALUE"""),"400953D0195257") -> 400953D0195257 | S17: =IFERROR(__xludf.DUMMYFUNCTION("""COMPUTED_VALUE"""),"MFJ400262SJ004829") -> MFJ400262SJ004829 | T17: =IFERROR(__xludf.DUMMYFUNCTION("""COMPUTED_VALUE"""),47833.0) -> 47833 | U17: =IFERROR(__xludf.DUMMYFUNCTION("""COMPUTED_VALUE"""),"Berlaku") -> Berlaku | V17: =IFERROR(__xludf.DUMMYFUNCTION("""COMPUTED_VALUE"""),46372.0) -> 46372 | W17: =IFERROR(__xludf.DUMMYFUNCTION("""COMPUTED_VALUE"""),"Berlaku") -> Berlaku | X17: =IFERROR(__xludf.DUMMYFUNCTION("""COMPUTED_VALUE"""),46332.0) -> 46332 | Y17: =IFERROR(__xludf.DUMMYFUNCTION("""COMPUTED_VALUE"""),"Akan Habis") -> Akan Habis | Z17: =IFERROR(__xludf.DUMMYFUNCTION("""COMPUTED_VALUE"""),46332.0) -> 46332 | AA17: =IFERROR(__xludf.DUMMYFUNCTION("""COMPUTED_VALUE"""),"Berlaku") -> Berlaku | AB17: =IFERROR(__xludf.DUMMYFUNCTION("""COMPUTED_VALUE"""),46816.0) -> 46816 | AC17: =IFERROR(__xludf.DUMMYFUNCTION("""COMPUTED_VALUE"""),"Berlaku") -> Berlaku | AD17: =IFERROR(__xludf.DUMMYFUNCTION("""COMPUTED_VALUE"""),46459.0) -> 46459 | AE17: =IFERROR(__xludf.DUMMYFUNCTION("""COMPUTED_VALUE"""),"Berlaku") -> Berlaku | AF17: =IFERROR(__xludf.DUMMYFUNCTION("""COMPUTED_VALUE"""),"TUGU") -> TUGU | AG17: =IFERROR(__xludf.DUMMYFUNCTION("""COMPUTED_VALUE"""),"AKTIF ") -> AKTIF | AI17: =IFERROR(__xludf.DUMMYFUNCTION("""COMPUTED_VALUE"""),"Peremajaan E9557YB") -> Peremajaan E9557YB
A18: =IFERROR(__xludf.DUMMYFUNCTION("""COMPUTED_VALUE"""),26.0) -> 26 | B18: =IFERROR(__xludf.DUMMYFUNCTION("""COMPUTED_VALUE"""),"E9556YC") -> E9556YC | C18: =IFERROR(__xludf.DUMMYFUNCTION("""COMPUTED_VALUE"""),"8+8+8") -> 8+8+8 | D18: =IFERROR(__xludf.DUMMYFUNCTION("""COMPUTED_VALUE"""),24.0) -> 24 | E18: =IFERROR(__xludf.DUMMYFUNCTION("""COMPUTED_VALUE"""),"PT. PUSPITA CIPTA") -> PT. PUSPITA CIPTA | F18: =IFERROR(__xludf.DUMMYFUNCTION("""COMPUTED_VALUE"""),2025.0) -> 2025 | G18: =IFERROR(__xludf.DUMMYFUNCTION("""COMPUTED_VALUE"""),2025.0) -> 2025 | H18: =IFERROR(__xludf.DUMMYFUNCTION("""COMPUTED_VALUE"""),1.0) -> 1 | I18: =IFERROR(__xludf.DUMMYFUNCTION("""COMPUTED_VALUE"""),"4028T") -> 4028T | J18: =IFERROR(__xludf.DUMMYFUNCTION("""COMPUTED_VALUE"""),6374.0) -> 6374 | K18: =IFERROR(__xludf.DUMMYFUNCTION("""COMPUTED_VALUE"""),"EURO 5") -> EURO 5 | L18: =IFERROR(__xludf.DUMMYFUNCTION("""COMPUTED_VALUE"""),"Standart") -> Standart | M18: =IFERROR(__xludf.DUMMYFUNCTION("""COMPUTED_VALUE"""),"Geluran Adikarya") -> Geluran Adikarya | N18: =IFERROR(__xludf.DUMMYFUNCTION("""COMPUTED_VALUE"""),2015.0) -> 2015 | O18: =IFERROR(__xludf.DUMMYFUNCTION("""COMPUTED_VALUE"""),11.0) -> 11 | P18: =IFERROR(__xludf.DUMMYFUNCTION("""COMPUTED_VALUE"""),"AA") -> AA | Q18: =IFERROR(__xludf.DUMMYFUNCTION("""COMPUTED_VALUE"""),"MERCEDES BENZ") -> MERCEDES BENZ | R18: =IFERROR(__xludf.DUMMYFUNCTION("""COMPUTED_VALUE"""),"400953D0195053") -> 400953D0195053 | S18: =IFERROR(__xludf.DUMMYFUNCTION("""COMPUTED_VALUE"""),"MFJ400262SJ004770") -> MFJ400262SJ004770 | T18: =IFERROR(__xludf.DUMMYFUNCTION("""COMPUTED_VALUE"""),47833.0) -> 47833 | U18: =IFERROR(__xludf.DUMMYFUNCTION("""COMPUTED_VALUE"""),"Berlaku") -> Berlaku | V18: =IFERROR(__xludf.DUMMYFUNCTION("""COMPUTED_VALUE"""),46372.0) -> 46372 | W18: =IFERROR(__xludf.DUMMYFUNCTION("""COMPUTED_VALUE"""),"Berlaku") -> Berlaku | X18: =IFERROR(__xludf.DUMMYFUNCTION("""COMPUTED_VALUE"""),46332.0) -> 46332 | Y18: =IFERROR(__xludf.DUMMYFUNCTION("""COMPUTED_VALUE"""),"Akan Habis") -> Akan Habis | Z18: =IFERROR(__xludf.DUMMYFUNCTION("""COMPUTED_VALUE"""),46332.0) -> 46332 | AA18: =IFERROR(__xludf.DUMMYFUNCTION("""COMPUTED_VALUE"""),"Berlaku") -> Berlaku | AB18: =IFERROR(__xludf.DUMMYFUNCTION("""COMPUTED_VALUE"""),46817.0) -> 46817 | AC18: =IFERROR(__xludf.DUMMYFUNCTION("""COMPUTED_VALUE"""),"Berlaku") -> Berlaku | AD18: =IFERROR(__xludf.DUMMYFUNCTION("""COMPUTED_VALUE"""),46459.0) -> 46459 | AE18: =IFERROR(__xludf.DUMMYFUNCTION("""COMPUTED_VALUE"""),"Berlaku") -> Berlaku | AF18: =IFERROR(__xludf.DUMMYFUNCTION("""COMPUTED_VALUE"""),"TUGU") -> TUGU | AG18: =IFERROR(__xludf.DUMMYFUNCTION("""COMPUTED_VALUE"""),"AKTIF ") -> AKTIF | AI18: =IFERROR(__xludf.DUMMYFUNCTION("""COMPUTED_VALUE"""),"Peremajaan E9560YB") -> Peremajaan E9560YB
A19: =IFERROR(__xludf.DUMMYFUNCTION("""COMPUTED_VALUE"""),27.0) -> 27 | B19: =IFERROR(__xludf.DUMMYFUNCTION("""COMPUTED_VALUE"""),"E9493YC") -> E9493YC | C19: =IFERROR(__xludf.DUMMYFUNCTION("""COMPUTED_VALUE"""),"8+8+8") -> 8+8+8 | D19: =IFERROR(__xludf.DUMMYFUNCTION("""COMPUTED_VALUE"""),24.0) -> 24 | E19: =IFERROR(__xludf.DUMMYFUNCTION("""COMPUTED_VALUE"""),"PT. PUSPITA CIPTA") -> PT. PUSPITA CIPTA | F19: =IFERROR(__xludf.DUMMYFUNCTION("""COMPUTED_VALUE"""),2025.0) -> 2025 | G19: =IFERROR(__xludf.DUMMYFUNCTION("""COMPUTED_VALUE"""),2025.0) -> 2025 | H19: =IFERROR(__xludf.DUMMYFUNCTION("""COMPUTED_VALUE"""),1.0) -> 1 | I19: =IFERROR(__xludf.DUMMYFUNCTION("""COMPUTED_VALUE"""),"4028 T") -> 4028 T | J19: =IFERROR(__xludf.DUMMYFUNCTION("""COMPUTED_VALUE"""),6374.0) -> 6374 | K19: =IFERROR(__xludf.DUMMYFUNCTION("""COMPUTED_VALUE"""),"EURO 5") -> EURO 5 | L19: =IFERROR(__xludf.DUMMYFUNCTION("""COMPUTED_VALUE"""),"Standart") -> Standart | M19: =IFERROR(__xludf.DUMMYFUNCTION("""COMPUTED_VALUE"""),"Geluran Adikarya") -> Geluran Adikarya | N19: =IFERROR(__xludf.DUMMYFUNCTION("""COMPUTED_VALUE"""),2015.0) -> 2015 | O19: =IFERROR(__xludf.DUMMYFUNCTION("""COMPUTED_VALUE"""),11.0) -> 11 | P19: =IFERROR(__xludf.DUMMYFUNCTION("""COMPUTED_VALUE"""),"AA") -> AA | Q19: =IFERROR(__xludf.DUMMYFUNCTION("""COMPUTED_VALUE"""),"MERCEDES BENZ") -> MERCEDES BENZ | R19: =IFERROR(__xludf.DUMMYFUNCTION("""COMPUTED_VALUE"""),"400953D0177908") -> 400953D0177908 | S19: =IFERROR(__xludf.DUMMYFUNCTION("""COMPUTED_VALUE"""),"MFJ400262SJ004431") -> MFJ400262SJ004431 | T19: =IFERROR(__xludf.DUMMYFUNCTION("""COMPUTED_VALUE"""),47625.0) -> 47625 | U19: =IFERROR(__xludf.DUMMYFUNCTION("""COMPUTED_VALUE"""),"Berlaku") -> Berlaku | V19: =IFERROR(__xludf.DUMMYFUNCTION("""COMPUTED_VALUE"""),46529.0) -> 46529 | W19: =IFERROR(__xludf.DUMMYFUNCTION("""COMPUTED_VALUE"""),"Berlaku") -> Berlaku | X19: =IFERROR(__xludf.DUMMYFUNCTION("""COMPUTED_VALUE"""),46331.0) -> 46331 | Y19: =IFERROR(__xludf.DUMMYFUNCTION("""COMPUTED_VALUE"""),"Akan Habis") -> Akan Habis | Z19: =IFERROR(__xludf.DUMMYFUNCTION("""COMPUTED_VALUE"""),46331.0) -> 46331 | AA19: =IFERROR(__xludf.DUMMYFUNCTION("""COMPUTED_VALUE"""),"Berlaku") -> Berlaku | AB19: =IFERROR(__xludf.DUMMYFUNCTION("""COMPUTED_VALUE"""),46571.0) -> 46571 | AC19: =IFERROR(__xludf.DUMMYFUNCTION("""COMPUTED_VALUE"""),"Berlaku") -> Berlaku | AD19: =IFERROR(__xludf.DUMMYFUNCTION("""COMPUTED_VALUE"""),46340.0) -> 46340 | AE19: =IFERROR(__xludf.DUMMYFUNCTION("""COMPUTED_VALUE"""),"Berlaku") -> Berlaku | AF19: =IFERROR(__xludf.DUMMYFUNCTION("""COMPUTED_VALUE"""),"TUGU") -> TUGU | AG19: =IFERROR(__xludf.DUMMYFUNCTION("""COMPUTED_VALUE"""),"AKTIF ") -> AKTIF | AI19: =IFERROR(__xludf.DUMMYFUNCTION("""COMPUTED_VALUE"""),"Meremajakan MT E9389YB") -> Meremajakan MT E9389YB
A20: =IFERROR(__xludf.DUMMYFUNCTION("""COMPUTED_VALUE"""),29.0) -> 29 | B20: =IFERROR(__xludf.DUMMYFUNCTION("""COMPUTED_VALUE"""),"E9496YC") -> E9496YC | C20: =IFERROR(__xludf.DUMMYFUNCTION("""COMPUTED_VALUE"""),"8+8+8") -> 8+8+8 | D20: =IFERROR(__xludf.DUMMYFUNCTION("""COMPUTED_VALUE"""),24.0) -> 24 | E20: =IFERROR(__xludf.DUMMYFUNCTION("""COMPUTED_VALUE"""),"PT. PUSPITA CIPTA") -> PT. PUSPITA CIPTA | F20: =IFERROR(__xludf.DUMMYFUNCTION("""COMPUTED_VALUE"""),2025.0) -> 2025 | G20: =IFERROR(__xludf.DUMMYFUNCTION("""COMPUTED_VALUE"""),2025.0) -> 2025 | H20: =IFERROR(__xludf.DUMMYFUNCTION("""COMPUTED_VALUE"""),1.0) -> 1 | I20: =IFERROR(__xludf.DUMMYFUNCTION("""COMPUTED_VALUE"""),"4028 T") -> 4028 T | J20: =IFERROR(__xludf.DUMMYFUNCTION("""COMPUTED_VALUE"""),6374.0) -> 6374 | K20: =IFERROR(__xludf.DUMMYFUNCTION("""COMPUTED_VALUE"""),"EURO 5") -> EURO 5 | L20: =IFERROR(__xludf.DUMMYFUNCTION("""COMPUTED_VALUE"""),"Standart") -> Standart | M20: =IFERROR(__xludf.DUMMYFUNCTION("""COMPUTED_VALUE"""),"Geluran Adikarya") -> Geluran Adikarya | N20: =IFERROR(__xludf.DUMMYFUNCTION("""COMPUTED_VALUE"""),2015.0) -> 2015 | O20: =IFERROR(__xludf.DUMMYFUNCTION("""COMPUTED_VALUE"""),11.0) -> 11 | P20: =IFERROR(__xludf.DUMMYFUNCTION("""COMPUTED_VALUE"""),"AA") -> AA | Q20: =IFERROR(__xludf.DUMMYFUNCTION("""COMPUTED_VALUE"""),"MERCEDES BENZ") -> MERCEDES BENZ | R20: =IFERROR(__xludf.DUMMYFUNCTION("""COMPUTED_VALUE"""),"400953DO177878") -> 400953DO177878 | S20: =IFERROR(__xludf.DUMMYFUNCTION("""COMPUTED_VALUE"""),"MFJ400262SJ004429") -> MFJ400262SJ004429 | T20: =IFERROR(__xludf.DUMMYFUNCTION("""COMPUTED_VALUE"""),47625.0) -> 47625 | U20: =IFERROR(__xludf.DUMMYFUNCTION("""COMPUTED_VALUE"""),"Berlaku") -> Berlaku | V20: =IFERROR(__xludf.DUMMYFUNCTION("""COMPUTED_VALUE"""),46529.0) -> 46529 | W20: =IFERROR(__xludf.DUMMYFUNCTION("""COMPUTED_VALUE"""),"Berlaku") -> Berlaku | X20: =IFERROR(__xludf.DUMMYFUNCTION("""COMPUTED_VALUE"""),46331.0) -> 46331 | Y20: =IFERROR(__xludf.DUMMYFUNCTION("""COMPUTED_VALUE"""),"Akan Habis") -> Akan Habis | Z20: =IFERROR(__xludf.DUMMYFUNCTION("""COMPUTED_VALUE"""),46331.0) -> 46331 | AA20: =IFERROR(__xludf.DUMMYFUNCTION("""COMPUTED_VALUE"""),"Berlaku") -> Berlaku | AB20: =IFERROR(__xludf.DUMMYFUNCTION("""COMPUTED_VALUE"""),46570.0) -> 46570 | AC20: =IFERROR(__xludf.DUMMYFUNCTION("""COMPUTED_VALUE"""),"Berlaku") -> Berlaku | AD20: =IFERROR(__xludf.DUMMYFUNCTION("""COMPUTED_VALUE"""),46340.0) -> 46340 | AE20: =IFERROR(__xludf.DUMMYFUNCTION("""COMPUTED_VALUE"""),"Berlaku") -> Berlaku | AF20: =IFERROR(__xludf.DUMMYFUNCTION("""COMPUTED_VALUE"""),"TUGU") -> TUGU | AG20: =IFERROR(__xludf.DUMMYFUNCTION("""COMPUTED_VALUE"""),"AKTIF ") -> AKTIF | AI20: =IFERROR(__xludf.DUMMYFUNCTION("""COMPUTED_VALUE"""),"Meremajakan MT E9391YB") -> Meremajakan MT E9391YB
A21: =IFERROR(__xludf.DUMMYFUNCTION("""COMPUTED_VALUE"""),30.0) -> 30 | B21: =IFERROR(__xludf.DUMMYFUNCTION("""COMPUTED_VALUE"""),"E9512YC") -> E9512YC | C21: =IFERROR(__xludf.DUMMYFUNCTION("""COMPUTED_VALUE"""),"8+8+8") -> 8+8+8 | D21: =IFERROR(__xludf.DUMMYFUNCTION("""COMPUTED_VALUE"""),24.0) -> 24 | E21: =IFERROR(__xludf.DUMMYFUNCTION("""COMPUTED_VALUE"""),"PT. PUSPITA CIPTA") -> PT. PUSPITA CIPTA | F21: =IFERROR(__xludf.DUMMYFUNCTION("""COMPUTED_VALUE"""),2025.0) -> 2025 | G21: =IFERROR(__xludf.DUMMYFUNCTION("""COMPUTED_VALUE"""),2025.0) -> 2025 | H21: =IFERROR(__xludf.DUMMYFUNCTION("""COMPUTED_VALUE"""),1.0) -> 1 | I21: =IFERROR(__xludf.DUMMYFUNCTION("""COMPUTED_VALUE"""),"4028 T") -> 4028 T | J21: =IFERROR(__xludf.DUMMYFUNCTION("""COMPUTED_VALUE"""),6374.0) -> 6374 | K21: =IFERROR(__xludf.DUMMYFUNCTION("""COMPUTED_VALUE"""),"EURO 5") -> EURO 5 | L21: =IFERROR(__xludf.DUMMYFUNCTION("""COMPUTED_VALUE"""),"Standart") -> Standart | M21: =IFERROR(__xludf.DUMMYFUNCTION("""COMPUTED_VALUE"""),"Geluran Adikarya") -> Geluran Adikarya | N21: =IFERROR(__xludf.DUMMYFUNCTION("""COMPUTED_VALUE"""),2015.0) -> 2015 | O21: =IFERROR(__xludf.DUMMYFUNCTION("""COMPUTED_VALUE"""),11.0) -> 11 | P21: =IFERROR(__xludf.DUMMYFUNCTION("""COMPUTED_VALUE"""),"AA") -> AA | Q21: =IFERROR(__xludf.DUMMYFUNCTION("""COMPUTED_VALUE"""),"MERCEDES BENZ") -> MERCEDES BENZ | R21: =IFERROR(__xludf.DUMMYFUNCTION("""COMPUTED_VALUE"""),"400963001792246") -> 400963001792246 | S21: =IFERROR(__xludf.DUMMYFUNCTION("""COMPUTED_VALUE"""),"MFJ400262SJ004440") -> MFJ400262SJ004440 | T21: =IFERROR(__xludf.DUMMYFUNCTION("""COMPUTED_VALUE"""),47716.0) -> 47716 | U21: =IFERROR(__xludf.DUMMYFUNCTION("""COMPUTED_VALUE"""),"Berlaku") -> Berlaku | V21: =IFERROR(__xludf.DUMMYFUNCTION("""COMPUTED_VALUE"""),46620.0) -> 46620 | W21: =IFERROR(__xludf.DUMMYFUNCTION("""COMPUTED_VALUE"""),"Berlaku") -> Berlaku | X21: =IFERROR(__xludf.DUMMYFUNCTION("""COMPUTED_VALUE"""),46311.0) -> 46311 | Y21: =IFERROR(__xludf.DUMMYFUNCTION("""COMPUTED_VALUE"""),"Akan Habis") -> Akan Habis | Z21: =IFERROR(__xludf.DUMMYFUNCTION("""COMPUTED_VALUE"""),46311.0) -> 46311 | AA21: =IFERROR(__xludf.DUMMYFUNCTION("""COMPUTED_VALUE"""),"Akan Habis") -> Akan Habis | AB21: =IFERROR(__xludf.DUMMYFUNCTION("""COMPUTED_VALUE"""),46688.0) -> 46688 | AC21: =IFERROR(__xludf.DUMMYFUNCTION("""COMPUTED_VALUE"""),"Berlaku") -> Berlaku | AD21: =IFERROR(__xludf.DUMMYFUNCTION("""COMPUTED_VALUE"""),46332.0) -> 46332 | AE21: =IFERROR(__xludf.DUMMYFUNCTION("""COMPUTED_VALUE"""),"Berlaku") -> Berlaku | AF21: =IFERROR(__xludf.DUMMYFUNCTION("""COMPUTED_VALUE"""),"TUGU") -> TUGU | AG21: =IFERROR(__xludf.DUMMYFUNCTION("""COMPUTED_VALUE"""),"AKTIF ") -> AKTIF | AI21: =IFERROR(__xludf.DUMMYFUNCTION("""COMPUTED_VALUE"""),"Meremajakan MT E9446YB") -> Meremajakan MT E9446YB
A22: =IFERROR(__xludf.DUMMYFUNCTION("""COMPUTED_VALUE"""),31.0) -> 31 | B22: =IFERROR(__xludf.DUMMYFUNCTION("""COMPUTED_VALUE"""),"E9535YC") -> E9535YC | C22: =IFERROR(__xludf.DUMMYFUNCTION("""COMPUTED_VALUE"""),"8+8+8") -> 8+8+8 | D22: =IFERROR(__xludf.DUMMYFUNCTION("""COMPUTED_VALUE"""),24.0) -> 24 | E22: =IFERROR(__xludf.DUMMYFUNCTION("""COMPUTED_VALUE"""),"PT. PUSPITA CIPTA") -> PT. PUSPITA CIPTA | F22: =IFERROR(__xludf.DUMMYFUNCTION("""COMPUTED_VALUE"""),2025.0) -> 2025 | G22: =IFERROR(__xludf.DUMMYFUNCTION("""COMPUTED_VALUE"""),2025.0) -> 2025 | H22: =IFERROR(__xludf.DUMMYFUNCTION("""COMPUTED_VALUE"""),1.0) -> 1 | I22: =IFERROR(__xludf.DUMMYFUNCTION("""COMPUTED_VALUE"""),"4028 T") -> 4028 T | J22: =IFERROR(__xludf.DUMMYFUNCTION("""COMPUTED_VALUE"""),6374.0) -> 6374 | K22: =IFERROR(__xludf.DUMMYFUNCTION("""COMPUTED_VALUE"""),"EURO 5") -> EURO 5 | L22: =IFERROR(__xludf.DUMMYFUNCTION("""COMPUTED_VALUE"""),"Standart") -> Standart | M22: =IFERROR(__xludf.DUMMYFUNCTION("""COMPUTED_VALUE"""),"Geluran Adikarya") -> Geluran Adikarya | N22: =IFERROR(__xludf.DUMMYFUNCTION("""COMPUTED_VALUE"""),2014.0) -> 2014 | O22: =IFERROR(__xludf.DUMMYFUNCTION("""COMPUTED_VALUE"""),12.0) -> 12 | P22: =IFERROR(__xludf.DUMMYFUNCTION("""COMPUTED_VALUE"""),"AA") -> AA | Q22: =IFERROR(__xludf.DUMMYFUNCTION("""COMPUTED_VALUE"""),"MERCEDES BENZ") -> MERCEDES BENZ | R22: =IFERROR(__xludf.DUMMYFUNCTION("""COMPUTED_VALUE"""),"400953D0179262") -> 400953D0179262 | S22: =IFERROR(__xludf.DUMMYFUNCTION("""COMPUTED_VALUE"""),"MFJ400262SJ004445") -> MFJ400262SJ004445 | T22: =IFERROR(__xludf.DUMMYFUNCTION("""COMPUTED_VALUE"""),47779.0) -> 47779 | U22: =IFERROR(__xludf.DUMMYFUNCTION("""COMPUTED_VALUE"""),"Berlaku") -> Berlaku | V22: =IFERROR(__xludf.DUMMYFUNCTION("""COMPUTED_VALUE"""),46318.0) -> 46318 | W22: =IFERROR(__xludf.DUMMYFUNCTION("""COMPUTED_VALUE"""),"Akan Habis") -> Akan Habis | X22: =IFERROR(__xludf.DUMMYFUNCTION("""COMPUTED_VALUE"""),46337.0) -> 46337 | Y22: =IFERROR(__xludf.DUMMYFUNCTION("""COMPUTED_VALUE"""),"Akan Habis") -> Akan Habis | Z22: =IFERROR(__xludf.DUMMYFUNCTION("""COMPUTED_VALUE"""),46337.0) -> 46337 | AA22: =IFERROR(__xludf.DUMMYFUNCTION("""COMPUTED_VALUE"""),"Berlaku") -> Berlaku | AB22: =IFERROR(__xludf.DUMMYFUNCTION("""COMPUTED_VALUE"""),46719.0) -> 46719 | AC22: =IFERROR(__xludf.DUMMYFUNCTION("""COMPUTED_VALUE"""),"Berlaku") -> Berlaku | AD22: =IFERROR(__xludf.DUMMYFUNCTION("""COMPUTED_VALUE"""),46373.0) -> 46373 | AE22: =IFERROR(__xludf.DUMMYFUNCTION("""COMPUTED_VALUE"""),"Berlaku") -> Berlaku | AF22: =IFERROR(__xludf.DUMMYFUNCTION("""COMPUTED_VALUE"""),"TUGU") -> TUGU | AG22: =IFERROR(__xludf.DUMMYFUNCTION("""COMPUTED_VALUE"""),"AKTIF ") -> AKTIF | AI22: =IFERROR(__xludf.DUMMYFUNCTION("""COMPUTED_VALUE"""),"Meremajakan MT E9452YB") -> Meremajakan MT E9452YB
